{
 "cells": [
  {
   "cell_type": "code",
   "execution_count": 4,
   "metadata": {},
   "outputs": [],
   "source": [
    "import pandas as pd\n",
    "import glob\n",
    "from sklearn.preprocessing import MinMaxScaler\n",
    "from sklearn.model_selection import train_test_split\n",
    "from sklearn.linear_model import LogisticRegression\n",
    "from sklearn.metrics import classification_report, confusion_matrix"
   ]
  },
  {
   "cell_type": "code",
   "execution_count": 5,
   "metadata": {},
   "outputs": [],
   "source": [
    "# Paths to training and testing data folders\n",
    "train_folder = \"C:\\\\Users\\\\grays\\\\Downloads\\\\train\\\\train\\\\\"\n",
    "test_folder = \"C:\\\\Users\\\\grays\\\\Downloads\\\\test\\\\test\\\\\"\n",
    "\n",
    "# List all CSV files in the train folder\n",
    "train_files = glob.glob(train_folder + \"*.csv\")\n",
    "test_files = glob.glob(test_folder + \"*.csv\")\n",
    "\n",
    "# Function to load and concatenate CSV files from a list of file paths\n",
    "def load_and_concat(files):\n",
    "    df_list = []\n",
    "    for file in files:\n",
    "        df = pd.read_csv(file)\n",
    "        df_list.append(df)\n",
    "    return pd.concat(df_list, ignore_index=True)\n",
    "\n",
    "# Load and concatenate training and testing data\n",
    "train_df = load_and_concat(train_files)\n",
    "test_df = load_and_concat(test_files)"
   ]
  },
  {
   "cell_type": "code",
   "execution_count": 6,
   "metadata": {},
   "outputs": [],
   "source": [
    "def label_data(df):\n",
    "    df['label'] = (df['ack_flag_number'] < 0.4).astype(int)\n",
    "    return df\n",
    "\n",
    "# Label the training and testing data\n",
    "train_df = label_data(train_df)\n",
    "test_df = label_data(test_df)\n",
    "\n",
    "# Separate features and labels\n",
    "X_train = train_df.drop(columns=['label'])\n",
    "y_train = train_df['label']\n",
    "X_test = test_df.drop(columns=['label'])\n",
    "y_test = test_df['label']\n",
    "\n",
    "# Create a scaler object\n",
    "scaler = MinMaxScaler()\n",
    "\n",
    "# Fit the scaler to the training features and transform both training and testing features\n",
    "X_train_scaled = scaler.fit_transform(X_train)\n",
    "X_test_scaled = scaler.transform(X_test)\n",
    "\n",
    "# Convert the scaled features to DataFrames\n",
    "X_train_scaled_df = pd.DataFrame(X_train_scaled, columns=X_train.columns)\n",
    "X_test_scaled_df = pd.DataFrame(X_test_scaled, columns=X_test.columns)"
   ]
  },
  {
   "cell_type": "code",
   "execution_count": 7,
   "metadata": {},
   "outputs": [
    {
     "name": "stdout",
     "output_type": "stream",
     "text": [
      "[[ 188870     418]\n",
      " [    447 1424447]]\n",
      "              precision    recall  f1-score   support\n",
      "\n",
      "           0       1.00      1.00      1.00    189288\n",
      "           1       1.00      1.00      1.00   1424894\n",
      "\n",
      "    accuracy                           1.00   1614182\n",
      "   macro avg       1.00      1.00      1.00   1614182\n",
      "weighted avg       1.00      1.00      1.00   1614182\n",
      "\n"
     ]
    }
   ],
   "source": [
    "model = LogisticRegression()\n",
    "\n",
    "# Train the model\n",
    "model.fit(X_train_scaled_df, y_train)\n",
    "\n",
    "# Make predictions\n",
    "y_pred = model.predict(X_test_scaled_df)\n",
    "\n",
    "# Evaluate the model\n",
    "print(confusion_matrix(y_test, y_pred))\n",
    "print(classification_report(y_test, y_pred))"
   ]
  },
  {
   "cell_type": "code",
   "execution_count": 9,
   "metadata": {},
   "outputs": [
    {
     "ename": "ValueError",
     "evalue": "\nAll the 3 fits failed.\nIt is very likely that your model is misconfigured.\nYou can try to debug the error by setting error_score='raise'.\n\nBelow are more details about the failures:\n--------------------------------------------------------------------------------\n2 fits failed with the following error:\nTraceback (most recent call last):\n  File \"c:\\Users\\grays\\AppData\\Local\\Programs\\Python\\Python39\\lib\\site-packages\\sklearn\\model_selection\\_validation.py\", line 888, in _fit_and_score\n    estimator.fit(X_train, y_train, **fit_params)\n  File \"c:\\Users\\grays\\AppData\\Local\\Programs\\Python\\Python39\\lib\\site-packages\\sklearn\\base.py\", line 1473, in wrapper\n    return fit_method(estimator, *args, **kwargs)\n  File \"c:\\Users\\grays\\AppData\\Local\\Programs\\Python\\Python39\\lib\\site-packages\\sklearn\\linear_model\\_logistic.py\", line 1223, in fit\n    X, y = self._validate_data(\n  File \"c:\\Users\\grays\\AppData\\Local\\Programs\\Python\\Python39\\lib\\site-packages\\sklearn\\base.py\", line 650, in _validate_data\n    X, y = check_X_y(X, y, **check_params)\n  File \"c:\\Users\\grays\\AppData\\Local\\Programs\\Python\\Python39\\lib\\site-packages\\sklearn\\utils\\validation.py\", line 1273, in check_X_y\n    X = check_array(\n  File \"c:\\Users\\grays\\AppData\\Local\\Programs\\Python\\Python39\\lib\\site-packages\\sklearn\\utils\\validation.py\", line 1007, in check_array\n    array = _asarray_with_order(array, order=order, dtype=dtype, xp=xp)\n  File \"c:\\Users\\grays\\AppData\\Local\\Programs\\Python\\Python39\\lib\\site-packages\\sklearn\\utils\\_array_api.py\", line 746, in _asarray_with_order\n    array = numpy.asarray(array, order=order, dtype=dtype)\nnumpy.core._exceptions._ArrayMemoryError: Unable to allocate 1.60 GiB for an array with shape (4773887, 45) and data type float64\n\n--------------------------------------------------------------------------------\n1 fits failed with the following error:\nTraceback (most recent call last):\n  File \"c:\\Users\\grays\\AppData\\Local\\Programs\\Python\\Python39\\lib\\site-packages\\sklearn\\model_selection\\_validation.py\", line 888, in _fit_and_score\n    estimator.fit(X_train, y_train, **fit_params)\n  File \"c:\\Users\\grays\\AppData\\Local\\Programs\\Python\\Python39\\lib\\site-packages\\sklearn\\base.py\", line 1473, in wrapper\n    return fit_method(estimator, *args, **kwargs)\n  File \"c:\\Users\\grays\\AppData\\Local\\Programs\\Python\\Python39\\lib\\site-packages\\sklearn\\linear_model\\_logistic.py\", line 1223, in fit\n    X, y = self._validate_data(\n  File \"c:\\Users\\grays\\AppData\\Local\\Programs\\Python\\Python39\\lib\\site-packages\\sklearn\\base.py\", line 650, in _validate_data\n    X, y = check_X_y(X, y, **check_params)\n  File \"c:\\Users\\grays\\AppData\\Local\\Programs\\Python\\Python39\\lib\\site-packages\\sklearn\\utils\\validation.py\", line 1273, in check_X_y\n    X = check_array(\n  File \"c:\\Users\\grays\\AppData\\Local\\Programs\\Python\\Python39\\lib\\site-packages\\sklearn\\utils\\validation.py\", line 1007, in check_array\n    array = _asarray_with_order(array, order=order, dtype=dtype, xp=xp)\n  File \"c:\\Users\\grays\\AppData\\Local\\Programs\\Python\\Python39\\lib\\site-packages\\sklearn\\utils\\_array_api.py\", line 746, in _asarray_with_order\n    array = numpy.asarray(array, order=order, dtype=dtype)\nnumpy.core._exceptions._ArrayMemoryError: Unable to allocate 1.60 GiB for an array with shape (4773888, 45) and data type float64\n",
     "output_type": "error",
     "traceback": [
      "\u001b[1;31m---------------------------------------------------------------------------\u001b[0m",
      "\u001b[1;31mValueError\u001b[0m                                Traceback (most recent call last)",
      "Cell \u001b[1;32mIn[9], line 5\u001b[0m\n\u001b[0;32m      3\u001b[0m stratified_k_fold \u001b[38;5;241m=\u001b[39m StratifiedKFold(n_splits\u001b[38;5;241m=\u001b[39m\u001b[38;5;241m3\u001b[39m)\n\u001b[0;32m      4\u001b[0m scoring \u001b[38;5;241m=\u001b[39m [\u001b[38;5;124m'\u001b[39m\u001b[38;5;124maccuracy\u001b[39m\u001b[38;5;124m'\u001b[39m, \u001b[38;5;124m'\u001b[39m\u001b[38;5;124mprecision\u001b[39m\u001b[38;5;124m'\u001b[39m, \u001b[38;5;124m'\u001b[39m\u001b[38;5;124mrecall\u001b[39m\u001b[38;5;124m'\u001b[39m, \u001b[38;5;124m'\u001b[39m\u001b[38;5;124mf1\u001b[39m\u001b[38;5;124m'\u001b[39m]\n\u001b[1;32m----> 5\u001b[0m cv_results \u001b[38;5;241m=\u001b[39m \u001b[43mcross_validate\u001b[49m\u001b[43m(\u001b[49m\u001b[43mmodel\u001b[49m\u001b[43m,\u001b[49m\u001b[43m \u001b[49m\u001b[43mX_train_scaled_df\u001b[49m\u001b[43m,\u001b[49m\u001b[43m \u001b[49m\u001b[43my_train\u001b[49m\u001b[43m,\u001b[49m\u001b[43m \u001b[49m\u001b[43mcv\u001b[49m\u001b[38;5;241;43m=\u001b[39;49m\u001b[43mstratified_k_fold\u001b[49m\u001b[43m,\u001b[49m\u001b[43m \u001b[49m\u001b[43mscoring\u001b[49m\u001b[38;5;241;43m=\u001b[39;49m\u001b[43mscoring\u001b[49m\u001b[43m,\u001b[49m\u001b[43m \u001b[49m\u001b[43mn_jobs\u001b[49m\u001b[38;5;241;43m=\u001b[39;49m\u001b[38;5;241;43m-\u001b[39;49m\u001b[38;5;241;43m1\u001b[39;49m\u001b[43m)\u001b[49m\n\u001b[0;32m      8\u001b[0m \u001b[38;5;66;03m# Print cross-validation scores\u001b[39;00m\n\u001b[0;32m      9\u001b[0m \u001b[38;5;28mprint\u001b[39m(\u001b[38;5;124m\"\u001b[39m\u001b[38;5;124mCross-validation accuracy scores:\u001b[39m\u001b[38;5;124m\"\u001b[39m, cv_results[\u001b[38;5;124m'\u001b[39m\u001b[38;5;124mtest_accuracy\u001b[39m\u001b[38;5;124m'\u001b[39m])\n",
      "File \u001b[1;32mc:\\Users\\grays\\AppData\\Local\\Programs\\Python\\Python39\\lib\\site-packages\\sklearn\\utils\\_param_validation.py:213\u001b[0m, in \u001b[0;36mvalidate_params.<locals>.decorator.<locals>.wrapper\u001b[1;34m(*args, **kwargs)\u001b[0m\n\u001b[0;32m    207\u001b[0m \u001b[38;5;28;01mtry\u001b[39;00m:\n\u001b[0;32m    208\u001b[0m     \u001b[38;5;28;01mwith\u001b[39;00m config_context(\n\u001b[0;32m    209\u001b[0m         skip_parameter_validation\u001b[38;5;241m=\u001b[39m(\n\u001b[0;32m    210\u001b[0m             prefer_skip_nested_validation \u001b[38;5;129;01mor\u001b[39;00m global_skip_validation\n\u001b[0;32m    211\u001b[0m         )\n\u001b[0;32m    212\u001b[0m     ):\n\u001b[1;32m--> 213\u001b[0m         \u001b[38;5;28;01mreturn\u001b[39;00m func(\u001b[38;5;241m*\u001b[39margs, \u001b[38;5;241m*\u001b[39m\u001b[38;5;241m*\u001b[39mkwargs)\n\u001b[0;32m    214\u001b[0m \u001b[38;5;28;01mexcept\u001b[39;00m InvalidParameterError \u001b[38;5;28;01mas\u001b[39;00m e:\n\u001b[0;32m    215\u001b[0m     \u001b[38;5;66;03m# When the function is just a wrapper around an estimator, we allow\u001b[39;00m\n\u001b[0;32m    216\u001b[0m     \u001b[38;5;66;03m# the function to delegate validation to the estimator, but we replace\u001b[39;00m\n\u001b[0;32m    217\u001b[0m     \u001b[38;5;66;03m# the name of the estimator by the name of the function in the error\u001b[39;00m\n\u001b[0;32m    218\u001b[0m     \u001b[38;5;66;03m# message to avoid confusion.\u001b[39;00m\n\u001b[0;32m    219\u001b[0m     msg \u001b[38;5;241m=\u001b[39m re\u001b[38;5;241m.\u001b[39msub(\n\u001b[0;32m    220\u001b[0m         \u001b[38;5;124mr\u001b[39m\u001b[38;5;124m\"\u001b[39m\u001b[38;5;124mparameter of \u001b[39m\u001b[38;5;124m\\\u001b[39m\u001b[38;5;124mw+ must be\u001b[39m\u001b[38;5;124m\"\u001b[39m,\n\u001b[0;32m    221\u001b[0m         \u001b[38;5;124mf\u001b[39m\u001b[38;5;124m\"\u001b[39m\u001b[38;5;124mparameter of \u001b[39m\u001b[38;5;132;01m{\u001b[39;00mfunc\u001b[38;5;241m.\u001b[39m\u001b[38;5;18m__qualname__\u001b[39m\u001b[38;5;132;01m}\u001b[39;00m\u001b[38;5;124m must be\u001b[39m\u001b[38;5;124m\"\u001b[39m,\n\u001b[0;32m    222\u001b[0m         \u001b[38;5;28mstr\u001b[39m(e),\n\u001b[0;32m    223\u001b[0m     )\n",
      "File \u001b[1;32mc:\\Users\\grays\\AppData\\Local\\Programs\\Python\\Python39\\lib\\site-packages\\sklearn\\model_selection\\_validation.py:443\u001b[0m, in \u001b[0;36mcross_validate\u001b[1;34m(estimator, X, y, groups, scoring, cv, n_jobs, verbose, fit_params, params, pre_dispatch, return_train_score, return_estimator, return_indices, error_score)\u001b[0m\n\u001b[0;32m    422\u001b[0m parallel \u001b[38;5;241m=\u001b[39m Parallel(n_jobs\u001b[38;5;241m=\u001b[39mn_jobs, verbose\u001b[38;5;241m=\u001b[39mverbose, pre_dispatch\u001b[38;5;241m=\u001b[39mpre_dispatch)\n\u001b[0;32m    423\u001b[0m results \u001b[38;5;241m=\u001b[39m parallel(\n\u001b[0;32m    424\u001b[0m     delayed(_fit_and_score)(\n\u001b[0;32m    425\u001b[0m         clone(estimator),\n\u001b[1;32m   (...)\u001b[0m\n\u001b[0;32m    440\u001b[0m     \u001b[38;5;28;01mfor\u001b[39;00m train, test \u001b[38;5;129;01min\u001b[39;00m indices\n\u001b[0;32m    441\u001b[0m )\n\u001b[1;32m--> 443\u001b[0m \u001b[43m_warn_or_raise_about_fit_failures\u001b[49m\u001b[43m(\u001b[49m\u001b[43mresults\u001b[49m\u001b[43m,\u001b[49m\u001b[43m \u001b[49m\u001b[43merror_score\u001b[49m\u001b[43m)\u001b[49m\n\u001b[0;32m    445\u001b[0m \u001b[38;5;66;03m# For callable scoring, the return type is only know after calling. If the\u001b[39;00m\n\u001b[0;32m    446\u001b[0m \u001b[38;5;66;03m# return type is a dictionary, the error scores can now be inserted with\u001b[39;00m\n\u001b[0;32m    447\u001b[0m \u001b[38;5;66;03m# the correct key.\u001b[39;00m\n\u001b[0;32m    448\u001b[0m \u001b[38;5;28;01mif\u001b[39;00m \u001b[38;5;28mcallable\u001b[39m(scoring):\n",
      "File \u001b[1;32mc:\\Users\\grays\\AppData\\Local\\Programs\\Python\\Python39\\lib\\site-packages\\sklearn\\model_selection\\_validation.py:529\u001b[0m, in \u001b[0;36m_warn_or_raise_about_fit_failures\u001b[1;34m(results, error_score)\u001b[0m\n\u001b[0;32m    522\u001b[0m \u001b[38;5;28;01mif\u001b[39;00m num_failed_fits \u001b[38;5;241m==\u001b[39m num_fits:\n\u001b[0;32m    523\u001b[0m     all_fits_failed_message \u001b[38;5;241m=\u001b[39m (\n\u001b[0;32m    524\u001b[0m         \u001b[38;5;124mf\u001b[39m\u001b[38;5;124m\"\u001b[39m\u001b[38;5;130;01m\\n\u001b[39;00m\u001b[38;5;124mAll the \u001b[39m\u001b[38;5;132;01m{\u001b[39;00mnum_fits\u001b[38;5;132;01m}\u001b[39;00m\u001b[38;5;124m fits failed.\u001b[39m\u001b[38;5;130;01m\\n\u001b[39;00m\u001b[38;5;124m\"\u001b[39m\n\u001b[0;32m    525\u001b[0m         \u001b[38;5;124m\"\u001b[39m\u001b[38;5;124mIt is very likely that your model is misconfigured.\u001b[39m\u001b[38;5;130;01m\\n\u001b[39;00m\u001b[38;5;124m\"\u001b[39m\n\u001b[0;32m    526\u001b[0m         \u001b[38;5;124m\"\u001b[39m\u001b[38;5;124mYou can try to debug the error by setting error_score=\u001b[39m\u001b[38;5;124m'\u001b[39m\u001b[38;5;124mraise\u001b[39m\u001b[38;5;124m'\u001b[39m\u001b[38;5;124m.\u001b[39m\u001b[38;5;130;01m\\n\u001b[39;00m\u001b[38;5;130;01m\\n\u001b[39;00m\u001b[38;5;124m\"\u001b[39m\n\u001b[0;32m    527\u001b[0m         \u001b[38;5;124mf\u001b[39m\u001b[38;5;124m\"\u001b[39m\u001b[38;5;124mBelow are more details about the failures:\u001b[39m\u001b[38;5;130;01m\\n\u001b[39;00m\u001b[38;5;132;01m{\u001b[39;00mfit_errors_summary\u001b[38;5;132;01m}\u001b[39;00m\u001b[38;5;124m\"\u001b[39m\n\u001b[0;32m    528\u001b[0m     )\n\u001b[1;32m--> 529\u001b[0m     \u001b[38;5;28;01mraise\u001b[39;00m \u001b[38;5;167;01mValueError\u001b[39;00m(all_fits_failed_message)\n\u001b[0;32m    531\u001b[0m \u001b[38;5;28;01melse\u001b[39;00m:\n\u001b[0;32m    532\u001b[0m     some_fits_failed_message \u001b[38;5;241m=\u001b[39m (\n\u001b[0;32m    533\u001b[0m         \u001b[38;5;124mf\u001b[39m\u001b[38;5;124m\"\u001b[39m\u001b[38;5;130;01m\\n\u001b[39;00m\u001b[38;5;132;01m{\u001b[39;00mnum_failed_fits\u001b[38;5;132;01m}\u001b[39;00m\u001b[38;5;124m fits failed out of a total of \u001b[39m\u001b[38;5;132;01m{\u001b[39;00mnum_fits\u001b[38;5;132;01m}\u001b[39;00m\u001b[38;5;124m.\u001b[39m\u001b[38;5;130;01m\\n\u001b[39;00m\u001b[38;5;124m\"\u001b[39m\n\u001b[0;32m    534\u001b[0m         \u001b[38;5;124m\"\u001b[39m\u001b[38;5;124mThe score on these train-test partitions for these parameters\u001b[39m\u001b[38;5;124m\"\u001b[39m\n\u001b[1;32m   (...)\u001b[0m\n\u001b[0;32m    538\u001b[0m         \u001b[38;5;124mf\u001b[39m\u001b[38;5;124m\"\u001b[39m\u001b[38;5;124mBelow are more details about the failures:\u001b[39m\u001b[38;5;130;01m\\n\u001b[39;00m\u001b[38;5;132;01m{\u001b[39;00mfit_errors_summary\u001b[38;5;132;01m}\u001b[39;00m\u001b[38;5;124m\"\u001b[39m\n\u001b[0;32m    539\u001b[0m     )\n",
      "\u001b[1;31mValueError\u001b[0m: \nAll the 3 fits failed.\nIt is very likely that your model is misconfigured.\nYou can try to debug the error by setting error_score='raise'.\n\nBelow are more details about the failures:\n--------------------------------------------------------------------------------\n2 fits failed with the following error:\nTraceback (most recent call last):\n  File \"c:\\Users\\grays\\AppData\\Local\\Programs\\Python\\Python39\\lib\\site-packages\\sklearn\\model_selection\\_validation.py\", line 888, in _fit_and_score\n    estimator.fit(X_train, y_train, **fit_params)\n  File \"c:\\Users\\grays\\AppData\\Local\\Programs\\Python\\Python39\\lib\\site-packages\\sklearn\\base.py\", line 1473, in wrapper\n    return fit_method(estimator, *args, **kwargs)\n  File \"c:\\Users\\grays\\AppData\\Local\\Programs\\Python\\Python39\\lib\\site-packages\\sklearn\\linear_model\\_logistic.py\", line 1223, in fit\n    X, y = self._validate_data(\n  File \"c:\\Users\\grays\\AppData\\Local\\Programs\\Python\\Python39\\lib\\site-packages\\sklearn\\base.py\", line 650, in _validate_data\n    X, y = check_X_y(X, y, **check_params)\n  File \"c:\\Users\\grays\\AppData\\Local\\Programs\\Python\\Python39\\lib\\site-packages\\sklearn\\utils\\validation.py\", line 1273, in check_X_y\n    X = check_array(\n  File \"c:\\Users\\grays\\AppData\\Local\\Programs\\Python\\Python39\\lib\\site-packages\\sklearn\\utils\\validation.py\", line 1007, in check_array\n    array = _asarray_with_order(array, order=order, dtype=dtype, xp=xp)\n  File \"c:\\Users\\grays\\AppData\\Local\\Programs\\Python\\Python39\\lib\\site-packages\\sklearn\\utils\\_array_api.py\", line 746, in _asarray_with_order\n    array = numpy.asarray(array, order=order, dtype=dtype)\nnumpy.core._exceptions._ArrayMemoryError: Unable to allocate 1.60 GiB for an array with shape (4773887, 45) and data type float64\n\n--------------------------------------------------------------------------------\n1 fits failed with the following error:\nTraceback (most recent call last):\n  File \"c:\\Users\\grays\\AppData\\Local\\Programs\\Python\\Python39\\lib\\site-packages\\sklearn\\model_selection\\_validation.py\", line 888, in _fit_and_score\n    estimator.fit(X_train, y_train, **fit_params)\n  File \"c:\\Users\\grays\\AppData\\Local\\Programs\\Python\\Python39\\lib\\site-packages\\sklearn\\base.py\", line 1473, in wrapper\n    return fit_method(estimator, *args, **kwargs)\n  File \"c:\\Users\\grays\\AppData\\Local\\Programs\\Python\\Python39\\lib\\site-packages\\sklearn\\linear_model\\_logistic.py\", line 1223, in fit\n    X, y = self._validate_data(\n  File \"c:\\Users\\grays\\AppData\\Local\\Programs\\Python\\Python39\\lib\\site-packages\\sklearn\\base.py\", line 650, in _validate_data\n    X, y = check_X_y(X, y, **check_params)\n  File \"c:\\Users\\grays\\AppData\\Local\\Programs\\Python\\Python39\\lib\\site-packages\\sklearn\\utils\\validation.py\", line 1273, in check_X_y\n    X = check_array(\n  File \"c:\\Users\\grays\\AppData\\Local\\Programs\\Python\\Python39\\lib\\site-packages\\sklearn\\utils\\validation.py\", line 1007, in check_array\n    array = _asarray_with_order(array, order=order, dtype=dtype, xp=xp)\n  File \"c:\\Users\\grays\\AppData\\Local\\Programs\\Python\\Python39\\lib\\site-packages\\sklearn\\utils\\_array_api.py\", line 746, in _asarray_with_order\n    array = numpy.asarray(array, order=order, dtype=dtype)\nnumpy.core._exceptions._ArrayMemoryError: Unable to allocate 1.60 GiB for an array with shape (4773888, 45) and data type float64\n"
     ]
    }
   ],
   "source": [
    "from sklearn.model_selection import StratifiedKFold, cross_validate\n",
    "\n",
    "stratified_k_fold = StratifiedKFold(n_splits=3)\n",
    "scoring = ['accuracy', 'precision', 'recall', 'f1']\n",
    "cv_results = cross_validate(model, X_train_scaled_df, y_train, cv=stratified_k_fold, scoring=scoring, n_jobs=-1)\n",
    "\n",
    "\n",
    "# Print cross-validation scores\n",
    "print(\"Cross-validation accuracy scores:\", cv_results['test_accuracy'])\n",
    "print(\"Mean cross-validation accuracy:\", cv_results.mean())\n",
    "print(\"Cross-validation precision scores:\", cv_results['test_precision'])\n",
    "print(\"Mean cross-validation precision:\", cv_results['test_precision'].mean())\n",
    "print(\"Cross-validation recall scores:\", cv_results['test_recall'])\n",
    "print(\"Mean cross-validation recall:\", cv_results['test_recall'].mean())\n",
    "print(\"Cross-validation F1 scores:\", cv_results['test_f1'])\n",
    "print(\"Mean cross-validation F1:\", cv_results['test_f1'].mean())"
   ]
  }
 ],
 "metadata": {
  "kernelspec": {
   "display_name": "Python 3",
   "language": "python",
   "name": "python3"
  },
  "language_info": {
   "codemirror_mode": {
    "name": "ipython",
    "version": 3
   },
   "file_extension": ".py",
   "mimetype": "text/x-python",
   "name": "python",
   "nbconvert_exporter": "python",
   "pygments_lexer": "ipython3",
   "version": "3.9.7"
  }
 },
 "nbformat": 4,
 "nbformat_minor": 2
}
